(dp1
S'output'
p2
S"<class 'sqlite3.OperationalError'> no such table: accounts"
p3
sS'layer'
p4
S'/home/matt/Dev/web2py/applications/blog/controllers/invite_tool.py'
p5
sS'code'
p6
S"import uuid\ndef index():\n    return locals()\t\n\t\ndef getAccountCollection():\n\tjson = []\n\trows = db().select(db.accounts.ALL, orderby=db.accounts.name)\n\tfor row in rows:\n\t\tjson.append({'name': row.name, 'id': row.id})\n\t\t\n\treturn response.json(json)\n\t\ndef getInviteeCollection():\n\tjson = []\n\trows = db(db.invitees.account_id.contains(request.args)).select(orderby=db.invitees.first_name)\n\tfor row in rows:\n\t\tjson.append({'id': row.id, 'uuid': row.uuid, 'first_name': row.first_name, 'last_name': row.last_name, 'email': row.email})\n\t\t\n\treturn response.json(json)\n\t\ndef postInvitee():\n    form = SQLFORM(db.invitees)\n    request.post_vars.uuid = uuid.uuid1()\n    if form.accepts(request, formname=None):\n        return uuid.uuid1()\n    elif form.errors:\n        return TABLE(*[TR(k, v) for k, v in form.errors.items()])\n\nresponse._vars=response._caller(getAccountCollection)\n"
p7
sS'snapshot'
p8
(dp9
sS'traceback'
p10
S'Traceback (most recent call last):\n  File "/home/matt/Dev/web2py/gluon/restricted.py", line 227, in restricted\n    exec ccode in environment\n  File "/home/matt/Dev/web2py/applications/blog/controllers/invite_tool.py", line 29, in <module>\n  File "/home/matt/Dev/web2py/gluon/globals.py", line 412, in <lambda>\n    self._caller = lambda f: f()\n  File "/home/matt/Dev/web2py/applications/blog/controllers/invite_tool.py", line 7, in getAccountCollection\n    rows = db().select(db.accounts.ALL, orderby=db.accounts.name)\n  File "/home/matt/Dev/web2py/gluon/packages/dal/pydal/objects.py", line 1986, in select\n    return adapter.select(self.query,fields,attributes)\n  File "/home/matt/Dev/web2py/gluon/packages/dal/pydal/adapters/sqlite.py", line 122, in select\n    return super(SQLiteAdapter, self).select(query, fields, attributes)\n  File "/home/matt/Dev/web2py/gluon/packages/dal/pydal/adapters/base.py", line 1258, in select\n    return self._select_aux(sql,fields,attributes)\n  File "/home/matt/Dev/web2py/gluon/packages/dal/pydal/adapters/base.py", line 1215, in _select_aux\n    self.execute(sql)\n  File "/home/matt/Dev/web2py/gluon/packages/dal/pydal/adapters/base.py", line 1350, in execute\n    return self.log_execute(*a, **b)\n  File "/home/matt/Dev/web2py/gluon/packages/dal/pydal/adapters/base.py", line 1344, in log_execute\n    ret = self.cursor.execute(command, *a[1:], **b)\nOperationalError: no such table: accounts\n'
p11
s.